Workbook

Sheet Master
A1: Shop Url | B1: Emails | C1: Meeting title
A2: offdutystore.myshopify.com | B2: {=XLOOKUP(A2,'Meeting Link <> Brand Name'!H:H,'Meeting Link <> Brand Name'!E:E)} -> tejas.k@offduty.in; shahbaaz@offduty.in
A3: cosiq.myshopify.com | B3: {=XLOOKUP(A3,'Meeting Link <> Brand Name'!H:H,'Meeting Link <> Brand Name'!E:E)} -> #N/A
A4: flicka-cosmetics-india.myshopify.com | B4: {=XLOOKUP(A4,'Meeting Link <> Brand Name'!H:H,'Meeting Link <> Brand Name'!E:E)} -> fardeen@trustsignal.io
A5: bombay-shaving.myshopify.com | B5: {=XLOOKUP(A5,'Meeting Link <> Brand Name'!H:H,'Meeting Link <> Brand Name'!E:E)} -> #N/A
A6: makershala.myshopify.com | B6: {=XLOOKUP(A6,'Meeting Link <> Brand Name'!H:H,'Meeting Link <> Brand Name'!E:E)} -> #N/A
A7: 84494d-fc.myshopify.com | B7: {=XLOOKUP(A7,'Meeting Link <> Brand Name'!H:H,'Meeting Link <> Brand Name'!E:E)}
A8: ripped-up-nutritio.myshopify.com | B8: {=XLOOKUP(A8,'Meeting Link <> Brand Name'!H:H,'Meeting Link <> Brand Name'!E:E)} -> himanshu@rippedupnutrition.com
A9: mokobara.myshopify.com | B9: {=XLOOKUP(A9,'Meeting Link <> Brand Name'!H:H,'Meeting Link <> Brand Name'!E:E)} -> #N/A
A10: alpino-in.myshopify.com | B10: {=XLOOKUP(A10,'Meeting Link <> Brand Name'!H:H,'Meeting Link <> Brand Name'!E:E)} -> #N/A
A11: fixderma-skincare.myshopify.com | B11: {=XLOOKUP(A11,'Meeting Link <> Brand Name'!H:H,'Meeting Link <> Brand Name'!E:E)} -> prashant@trustsignal.io
A12: sujatra-sarees.myshopify.com | B12: {=XLOOKUP(A12,'Meeting Link <> Brand Name'!H:H,'Meeting Link <> Brand Name'!E:E)} -> #N/A
A13: deyga-in.myshopify.com | B13: {=XLOOKUP(A13,'Meeting Link <> Brand Name'!H:H,'Meeting Link <> Brand Name'!E:E)}
... A1102: 646888.myshopify.com | B1102: {=XLOOKUP(A1102,'Meeting Link <> Brand Name'!H:H,'Meeting Link <> Brand Name'!E:E)} -> #N/A

Sheet ShopUrl <> Brand Name
A1: name | B1: shopUrl
A2: Backdropsource AU | B2: mousestored.myshopify.com
A3: Interwove | B3: intervowe.myshopify.com
A4: DRUIDS | B4: lachicos.myshopify.com
A5: Odhanon | B5: 671342-2.myshopify.com
A6: Modibodi | B6: moddd-com.myshopify.com
A7: BrustroShop | B7: brustroshop.myshopify.com
A8: Athlos Activewear | B8: goathlos-com.myshopify.com
A9: Ikoho | B9: 204888.myshopify.com
A10: farmerr.in | B10: farmerr-in.myshopify.com
A11: Coolbeds | B11: cool-beds.myshopify.com
A12: Vlado's Himalayan Organics | B12: the-himalayan-organics.myshopify.com
... A830: Arctic Fox India | B830: arctic-fox-india.myshopify.com

Sheet Meeting Link <> Brand Name
A1: company | B1: date | C1: meeting_title | D1: meeting_link | E1: external_attendees | F1: internal_attendees | G1: meeting_id
B2: 46090.417 | C2: Little Rituals x Bitespeed | Bi-weekly Meet | D2: https://meet.google.com/xwc-xuie-qkr | E2: gaurang.narvania@littlerituals.in | F2: ayush.madan@bitespeed.co | G2: 01KK4AFA83YERCAA2DK6JCV9PX | H2: {=XLOOKUP(D2,Sheet1!E:E,Sheet1!B:B)} -> little-rituals-india.myshopify.com | J2: {=XLOOKUP(C2,'Fuzzy Brand Name Match'!B:B,'Fuzzy Brand Name Match'!D:D)} -> #N/A
B3: 46090.417 | C3: Rioware x Bitespeed | D3: https://meet.google.com/fnq-gund-ncg | F3: divya.joshi@bitespeed.co; akshita@bitespeed.co | G3: 01KK8JFBPFYF5GWGE7R32VS6PY | H3: {=XLOOKUP(D3,Sheet1!E:E,Sheet1!B:B)} | J3: {=XLOOKUP(C3,'Fuzzy Brand Name Match'!B:B,'Fuzzy Brand Name Match'!D:D)}
B4: 46090.438 | C4: The Be Life x Bitespeed | Weekly Cadence | D4: https://meet.google.com/ayk-goax-mxe | E4: abhishek.n@thebelife.co; abhishek.b@thebelife.co | F4: ayush.madan@bitespeed.co | G4: 01KK4AFA8AT8WQVPXP66VQT9YJ | H4: {=XLOOKUP(D4,Sheet1!E:E,Sheet1!B:B)} -> thebelife.myshopify.com | J4: {=XLOOKUP(C4,'Fuzzy Brand Name Match'!B:B,'Fuzzy Brand Name Match'!D:D)} -> #N/A
B5: 46090.438 | C5: Zevar : AI Voice Review | D5: https://meet.google.com/kzi-kknq-ehd | E5: akshaydoshi@zevaramaze.com | F5: raashik.kariappa@bitespeed.co | G5: 01KK3Y6PBNVQ82JZ8NVQD1DR5K | H5: {=XLOOKUP(D5,Sheet1!E:E,Sheet1!B:B)} -> #N/A | J5: {=XLOOKUP(C5,'Fuzzy Brand Name Match'!B:B,'Fuzzy Brand Name Match'!D:D)}
B6: 46090.458 | C6: Tangerine Jewelry x Bitespeed : Connect | D6: https://meet.google.com/tce-amqx-jyf | E6: aarohi.s@oxbowcreatives.com | F6: raashik.kariappa@bitespeed.co | G6: 01KK8HF9R0JPTVS50WX693ATTX | H6: {=XLOOKUP(D6,Sheet1!E:E,Sheet1!B:B)} -> #N/A | J6: {=XLOOKUP(C6,'Fuzzy Brand Name Match'!B:B,'Fuzzy Brand Name Match'!D:D)} -> 62aa65.myshopify.com
B7: 46090.458 | C7: Muse Beauty x Bitespeed | D7: https://meet.google.com/fir-cqxv-xxj | F7: divya.joshi@bitespeed.co; rohan@bitespeed.co | G7: 01KK8JAHDSN1QD3142XX7KFVP0 | H7: {=XLOOKUP(D7,Sheet1!E:E,Sheet1!B:B)} -> c66cd2-e0.myshopify.com | J7: {=XLOOKUP(C7,'Fuzzy Brand Name Match'!B:B,'Fuzzy Brand Name Match'!D:D)} -> #N/A
B8: 46090.469 | C8: 9yardz x Bitespeed | Bi-weekly Cadence | D8: https://meet.google.com/mdz-egby-tzy | E8: v.krishnamoorthy.v@gmail.com | F8: ayush.madan@bitespeed.co | G8: 01KK4AFA84CHT5HTKXHAV68WBN | H8: {=XLOOKUP(D8,Sheet1!E:E,Sheet1!B:B)} -> 9yardz.myshopify.com | J8: {=XLOOKUP(C8,'Fuzzy Brand Name Match'!B:B,'Fuzzy Brand Name Match'!D:D)} -> #N/A
B9: 46090.472 | C9: tanmay.dwivedi@bitespeed.co - Mon, 09 Mar 2026 16:51:44 IST - Untitled | D9: https://meet.google.com/rus-mrfs-zmy | G9: 01KK959RDVD0TS76YFABYYFZ60 | H9: {=XLOOKUP(D9,Sheet1!E:E,Sheet1!B:B)} -> therealb-in.myshopify.com | J9: {=XLOOKUP(C9,'Fuzzy Brand Name Match'!B:B,'Fuzzy Brand Name Match'!D:D)} -> #N/A
B10: 46090.479 | C10: Nature Fab Store | D10: https://meet.google.com/zxh-bevc-kjn | F10: akshita@bitespeed.co | G10: 01KK8MABZK3D9TKFZ1C2F3CFW7 | H10: {=XLOOKUP(D10,Sheet1!E:E,Sheet1!B:B)} -> #N/A | J10: {=XLOOKUP(C10,'Fuzzy Brand Name Match'!B:B,'Fuzzy Brand Name Match'!D:D)}
B11: 46090.479 | C11: VIP x Bitespeed | D11: https://meet.google.com/rtp-ohtj-bhz | E11: ananya.dubey@vipbags.com | F11: divyam@bitespeed.co | G11: 01KK7HY1ZCA44DBVZS7XJ3F37Y | H11: {=XLOOKUP(D11,Sheet1!E:E,Sheet1!B:B)} -> #N/A | J11: {=XLOOKUP(C11,'Fuzzy Brand Name Match'!B:B,'Fuzzy Brand Name Match'!D:D)}
B12: 46090.486 | C12: hardik@bitespeed.co - Mon, 09 Mar 2026 17:12:28 IST - Untitled | D12: https://meet.google.com/qqn-yjuk-izw?authuser=0 | G12: 01KK96FR2471VA6620HBNAA2MT | H12: {=XLOOKUP(D12,Sheet1!E:E,Sheet1!B:B)} -> #N/A | J12: {=XLOOKUP(C12,'Fuzzy Brand Name Match'!B:B,'Fuzzy Brand Name Match'!D:D)}
B13: 46090.49 | C13: Right4paws x Bitespeed | Trial Kickoff | D13: https://meet.google.com/yue-gcxt-ffq | E13: johan@petprakalp.com; tahaniyat@voynicmedia.com; tharun@voynicmedia.com | F13: divya.joshi@bitespeed.co; prateek.gautam@bitespeed.co; suhasini@bitespeed.co; sakar.shubham@bitespeed.co | G13: 01KK95ZAXRSBEF1RG9XR325BEH | H13: {=XLOOKUP(D13,Sheet1!E:E,Sheet1!B:B)} -> #N/A | J13: {=XLOOKUP(C13,'Fuzzy Brand Name Match'!B:B,'Fuzzy Brand Name Match'!D:D)}
B14: 46090.49 | C14: Nutristar x Bitespeed | Weekly Cadence | D14: https://meet.google.com/akg-byyh-mfm | E14: kunal@nutristar.in; shivam@nutristar.in; mohit@nutristar.in | F14: ayush.madan@bitespeed.co | G14: 01KK4AFAFMN4DTKXAYFDMH9HMA | H14: {=XLOOKUP(D14,Sheet1!E:E,Sheet1!B:B)} -> 7e2377-6b.myshopify.com | J14: {=XLOOKUP(C14,'Fuzzy Brand Name Match'!B:B,'Fuzzy Brand Name Match'!D:D)} -> #N/A
B15: 46090.5 | C15: The Clothing Factory - Discussion | D15: https://meet.google.com/rvq-wfsx-dpw | F15: rohan@bitespeed.co | G15: 01KK8SSME69XZ1JZJQVXSRF05S | H15: {=XLOOKUP(D15,Sheet1!E:E,Sheet1!B:B)} -> #N/A | J15: {=XLOOKUP(C15,'Fuzzy Brand Name Match'!B:B,'Fuzzy Brand Name Match'!D:D)} -> the-clothing-factory-shop.myshopify.com
B16: 46090.51 | C16: tushita@bitespeed.co - Mon, 09 Mar 2026 17:44:13 IST - Untitled | D16: https://meet.google.com/qso-gpza-oaj | G16: 01KK989W0MSX4JVJ2GJMZR7AYB | H16: {=XLOOKUP(D16,Sheet1!E:E,Sheet1!B:B)} -> #N/A | J16: {=XLOOKUP(C16,'Fuzzy Brand Name Match'!B:B,'Fuzzy Brand Name Match'!D:D)}
B17: 46090.562 | C17: Dominic Smith and navneeth | Bitespeed | D17: https://meet.google.com/wdh-waym-juq | E17: dom@bisonproducts.co.uk | F17: navneeth@bitespeed.co; arthi@bitespeed.co; sandy.bdr@bitespeed.co; tarrush@bitespeed.co; akshay@bitespeed.co | G17: 01KK4CDMWJ87H5CVDKBE3Y10DJ | H17: {=XLOOKUP(D17,Sheet1!E:E,Sheet1!B:B)} -> #N/A | J17: {=XLOOKUP(C17,'Fuzzy Brand Name Match'!B:B,'Fuzzy Brand Name Match'!D:D)}
B18: 46090.573 | C18: V / Aaryaman | D18: https://meet.google.com/bnn-pxex-qzx | F18: aaryaman.kollara@bitespeed.co; suhasini@bitespeed.co | G18: 01KK9BDEZ0TCZ8BPJDAY4901GB | H18: {=XLOOKUP(D18,Sheet1!E:E,Sheet1!B:B)} -> #N/A | J18: {=XLOOKUP(C18,'Fuzzy Brand Name Match'!B:B,'Fuzzy Brand Name Match'!D:D)}
B19: 46090.573 | C19: Onboarding Sync | D19: https://meet.google.com/awb-zkoa-kor | F19: vidya.v@bitespeed.co; tanul@bitespeed.co; suhasini@bitespeed.co | G19: 01KK9CQN32PGTXC23BWTNH30MG | H19: {=XLOOKUP(D19,Sheet1!E:E,Sheet1!B:B)} -> #N/A | J19: {=XLOOKUP(C19,'Fuzzy Brand Name Match'!B:B,'Fuzzy Brand Name Match'!D:D)}
B20: 46090.625 | C20: L1 Sync - Knowledge + Ticket Context | D20: https://meet.google.com/igp-bamg-wpf | F20: sudar@bitespeed.co; abhinav.aggarwal@bitespeed.co; ujjwal@bitespeed.co; karan@bitespeed.co; adityachoudhury@bitespeed.co; yash@bitespeed.co; arindam@bitespeed.co; aman@bitespeed.co | G20: 01KK4JNAQKRTTHA8BMHA5XFT1T | H20: {=XLOOKUP(D20,Sheet1!E:E,Sheet1!B:B)} -> #N/A | J20: {=XLOOKUP(C20,'Fuzzy Brand Name Match'!B:B,'Fuzzy Brand Name Match'!D:D)}
B21: 46091.25 | C21: Brustro : AI Voice Review | D21: https://meet.google.com/tog-fqqw-zsc | E21: brustro@creativehands.in | F21: raashik.kariappa@bitespeed.co | G21: 01KK8PDEEBR6PMV6ZM7GYATH7X | H21: {=XLOOKUP(D21,Sheet1!E:E,Sheet1!B:B)} -> #N/A | J21: {=XLOOKUP(C21,'Fuzzy Brand Name Match'!B:B,'Fuzzy Brand Name Match'!D:D)}
B22: 46091.271 | C22: Oregion x Bitespeed : Broadcast Ideas | D22: https://meet.google.com/kzc-fkmj-non | E22: info@oregion.in | F22: raashik.kariappa@bitespeed.co | G22: 01KK9BTV3456VJDZ8MY2FXPS03 | H22: {=XLOOKUP(D22,Sheet1!E:E,Sheet1!B:B)} -> #N/A | J22: {=XLOOKUP(C22,'Fuzzy Brand Name Match'!B:B,'Fuzzy Brand Name Match'!D:D)}
B23: 46091.271 | C23: Aguante X BiteSpeed || Weekly Meet | D23: https://meet.google.com/bus-zhbg-sqq | E23: ASLAM BODY BASICS <admin@bodybasics.in> | F23: ayush.madan@bitespeed.co | G23: 01KK688ZK83KCQAAGMYA4K2XSV | H23: {=XLOOKUP(D23,Sheet1!E:E,Sheet1!B:B)} -> aguanteindia.myshopify.com | J23: {=XLOOKUP(C23,'Fuzzy Brand Name Match'!B:B,'Fuzzy Brand Name Match'!D:D)} -> #N/A
B24: 46091.271 | C24: The Secret Of Tea - Market and WA | D24: https://meet.google.com/vic-wwse-nbz | E24: sukanya@thrivom.com | F24: shivam.agarwal@bitespeed.co | G24: 01KK9A0WQWKT5GJRSB5YH2V9KD | H24: {=XLOOKUP(D24,Sheet1!E:E,Sheet1!B:B)} -> #N/A | J24: {=XLOOKUP(C24,'Fuzzy Brand Name Match'!B:B,'Fuzzy Brand Name Match'!D:D)}
B25: 46091.274 | C25: rohan@bitespeed.co - Tue, 10 Mar 2026 12:03:54 IST - Untitled | D25: https://meet.google.com/yif-vsrq-iqw | G25: 01KKB77EA2J1S4PMW44C195F7T | H25: {=XLOOKUP(D25,Sheet1!E:E,Sheet1!B:B)} -> #N/A | J25: {=XLOOKUP(C25,'Fuzzy Brand Name Match'!B:B,'Fuzzy Brand Name Match'!D:D)}
B26: 46091.281 | C26: Yardley - Number onboarding | D26: https://meet.google.com/gfm-vpxk-xhc | F26: rohan@bitespeed.co | G26: 01KK9S461J7R8GM6F1JRY0GS0Z | H26: {=XLOOKUP(D26,Sheet1!E:E,Sheet1!B:B)} -> yardley-london-india.myshopify.com | J26: {=XLOOKUP(C26,'Fuzzy Brand Name Match'!B:B,'Fuzzy Brand Name Match'!D:D)} -> #N/A
B27: 46091.292 | C27: GleuHR x Bitespeed | Number Onboarding | D27: https://meet.google.com/vdm-cbrt-onf | E27: amanpreet@gleuhr.com | F27: ayush.madan@bitespeed.co; rohan@bitespeed.co | G27: 01KK9310DQ48Z3V7MNNY9NCKES | H27: {=XLOOKUP(D27,Sheet1!E:E,Sheet1!B:B)} -> #N/A | J27: {=XLOOKUP(C27,'Fuzzy Brand Name Match'!B:B,'Fuzzy Brand Name Match'!D:D)} -> gleuhr.myshopify.com
B28: 46091.292 | C28: Bitespeed X Neeman's | D28: https://meet.google.com/dzj-uvee-ssq | E28: anamika.k@neemans.com; kaushal@neemans.com; kuldeep@neemans.com; abhinav@neemans.com; shankar.s@neemans.com | F28: prachi.chodha@bitespeed.co | G28: 01KK8XNN5A2A3EF2KZSGE2SA1G | H28: {=XLOOKUP(D28,Sheet1!E:E,Sheet1!B:B)} -> #N/A | J28: {=XLOOKUP(C28,'Fuzzy Brand Name Match'!B:B,'Fuzzy Brand Name Match'!D:D)}
B29: 46091.299 | C29: rohan@bitespeed.co - Tue, 10 Mar 2026 12:42:14 IST - Untitled | D29: https://meet.google.com/gfm-vpxk-xhc | G29: 01KKB9DMCD7HA9BA05YMNB7F3Z | H29: {=XLOOKUP(D29,Sheet1!E:E,Sheet1!B:B)} -> yardley-london-india.myshopify.com | J29: {=XLOOKUP(C29,'Fuzzy Brand Name Match'!B:B,'Fuzzy Brand Name Match'!D:D)} -> #N/A
B30: 46091.312 | C30: Frido X Bitespeed || AI Voice Broadcast | D30: https://meet.google.com/ijk-ywmm-koq | E30: amaan.k@myfrido.com | F30: pravandan.srivastava@bitespeed.co; jaideep@bitespeed.co; divyam@bitespeed.co; ritesh@bitespeed.co | G30: 01KK9AGRMFK81FT2EDKNBMVD9F | H30: {=XLOOKUP(D30,Sheet1!E:E,Sheet1!B:B)} -> #N/A | J30: {=XLOOKUP(C30,'Fuzzy Brand Name Match'!B:B,'Fuzzy Brand Name Match'!D:D)}
B31: 46091.312 | C31: Maskman - WA onboarding | D31: https://meet.google.com/txq-ngrw-okf | E31: vaishnavikhandelwaljpr@gmail.com | F31: shivam.agarwal@bitespeed.co | G31: 01KK9A2M79MYWSFSW2NECEKZBV | H31: {=XLOOKUP(D31,Sheet1!E:E,Sheet1!B:B)} -> #N/A | J31: {=XLOOKUP(C31,'Fuzzy Brand Name Match'!B:B,'Fuzzy Brand Name Match'!D:D)}
B32: 46091.344 | C32: Cyclamen x Bitespeed | D32: https://meet.google.com/shh-xjcf-ihk | F32: divya.joshi@bitespeed.co | G32: 01KKBBNPSGZ08BHAZ2EVGFNSXH | H32: {=XLOOKUP(D32,Sheet1!E:E,Sheet1!B:B)} -> #N/A | J32: {=XLOOKUP(C32,'Fuzzy Brand Name Match'!B:B,'Fuzzy Brand Name Match'!D:D)}
B33: 46091.375 | C33: Ryder's Arena x BiteSpeed | Weekly Meet | D33: https://meet.google.com/edm-ekzn-hpk | E33: tarunsyadav15@gmail.com | F33: ayush.madan@bitespeed.co; nandini@bitespeed.co | G33: 01KJYZP8S902EPMVQ1BQ7HFXY3 | H33: {=XLOOKUP(D33,Sheet1!E:E,Sheet1!B:B)} -> 8cbfb1-7e.myshopify.com | J33: {=XLOOKUP(C33,'Fuzzy Brand Name Match'!B:B,'Fuzzy Brand Name Match'!D:D)} -> #N/A
B34: 46091.396 | C34: L1 KT | ContextTransfer | Complete Handover | D34: https://meet.google.com/krz-jwyj-ptq | F34: sudar@bitespeed.co; harshwardhan@bitespeed.co; abhinav.aggarwal@bitespeed.co; ujjwal@bitespeed.co; karan@bitespeed.co; adityachoudhury@bitespeed.co; nandini@bitespeed.co | G34: 01KK9HN5N30SJHVGMP8WP06FN8 | H34: {=XLOOKUP(D34,Sheet1!E:E,Sheet1!B:B)} -> #N/A | J34: {=XLOOKUP(C34,'Fuzzy Brand Name Match'!B:B,'Fuzzy Brand Name Match'!D:D)}
B35: 46091.396 | C35: Bartisans x Bitespeed | Weekly Meet | D35: https://meet.google.com/ydz-ztwa-oez | E35: social@bartisans.in | F35: ayush.madan@bitespeed.co; sharmi@bitespeed.co | G35: 01KK6G0545WHVWRZZA1NXQEM84 | H35: {=XLOOKUP(D35,Sheet1!E:E,Sheet1!B:B)} -> rtcpl.myshopify.com | J35: {=XLOOKUP(C35,'Fuzzy Brand Name Match'!B:B,'Fuzzy Brand Name Match'!D:D)} -> #N/A
B36: 46091.396 | C36: Bartisans x Bitespeed | D36: https://meet.google.com/hwq-iniw-mxt | F36: ayush.madan@bitespeed.co | G36: 01KKBHTXKQVEWTPMCZ4A13H930 | H36: {=XLOOKUP(D36,Sheet1!E:E,Sheet1!B:B)} -> rtcpl.myshopify.com | J36: {=XLOOKUP(C36,'Fuzzy Brand Name Match'!B:B,'Fuzzy Brand Name Match'!D:D)} -> #N/A
B37: 46091.403 | C37: nandini@bitespeed.co - Tue, 10 Mar 2026 15:11:24 IST - Untitled | D37: https://meet.google.com/krz-jwyj-ptq | G37: 01KKBHYRHKXWXE11YWPN0W67EK | H37: {=XLOOKUP(D37,Sheet1!E:E,Sheet1!B:B)} -> #N/A | J37: {=XLOOKUP(C37,'Fuzzy Brand Name Match'!B:B,'Fuzzy Brand Name Match'!D:D)}
B38: 46091.417 | C38: Bitespeed - Books Closure for FY 2025–26 | D38: https://teams.microsoft.com/l/meetup-join/19:meeting_Y2U4MTM0ZWQtNjM3Ni00MmVhLWJmYWItNTA5OWUyYmMyOWNm@thread.v2/0?context={"Tid":"8870f78b-4e5a-4623-ac14-a96a3c669710","Oid":"7690c45a-bda3-45a7-8d6a-fed4829ab462"} | E38: Kalpesh Jain <kalpesh@m2k.co.in>; Gokulnath.I <gokulnath.i@m2k.co.in>; Om Prakash.K <omprakash.k@m2k.co.in> | F38: vinayak@bitespeed.co; aman@bitespeed.co; mehul@bitespeed.co; parth@bitespeed.co; anish@bitespeed.co | G38: 01KK9F404NWCVXS7Z68D4R8E7V | H38: {=XLOOKUP(D38,Sheet1!E:E,Sheet1!B:B)} -> #N/A | J38: {=XLOOKUP(C38,'Fuzzy Brand Name Match'!B:B,'Fuzzy Brand Name Match'!D:D)}
B39: 46091.427 | C39: Dioste Connect | D39: https://meet.google.com/yxm-zdrx-uxf | E39: dioste10@gmail.com | F39: shivam.agarwal@bitespeed.co | G39: 01KK9A9MXVQX1F8QX8F7PKNMFV | H39: {=XLOOKUP(D39,Sheet1!E:E,Sheet1!B:B)} -> #N/A | J39: {=XLOOKUP(C39,'Fuzzy Brand Name Match'!B:B,'Fuzzy Brand Name Match'!D:D)}
B40: 46091.438 | C40: Luka Originals x Bitespeed | D40: https://meet.google.com/ysr-fcxv-gtx | E40: lukaoriginals2023@gmail.com; business.mail.kapil@gmail.com | F40: divya.joshi@bitespeed.co; rohan@bitespeed.co; mahita.potunuri@bitespeed.co; sakar.shubham@bitespeed.co | G40: 01KK9GVNRT4V8E6C88BVNHXAD4 | H40: {=XLOOKUP(D40,Sheet1!E:E,Sheet1!B:B)} -> #N/A | J40: {=XLOOKUP(C40,'Fuzzy Brand Name Match'!B:B,'Fuzzy Brand Name Match'!D:D)}
...

Sheet Sheet6
A1: {=UNIQUE(VSTACK('Meeting Link <> Brand Name'!H:H,'Meeting Link <> Brand Name'!I:I))}
A2: little-rituals-india.myshopify.com
A3: thebelife.myshopify.com
A4: #N/A
A5: c66cd2-e0.myshopify.com
A6: 9yardz.myshopify.com
A7: therealb-in.myshopify.com
A8: 7e2377-6b.myshopify.com
A9: aguanteindia.myshopify.com
A10: yardley-london-india.myshopify.com
A11: 8cbfb1-7e.myshopify.com
A12: rtcpl.myshopify.com
A13: preety-pixie.myshopify.com
A14: inespresso.myshopify.com
A15: chotteylal-sons.myshopify.com
A16: oracura.myshopify.com
... A700: evolve-care-1.myshopify.com

Sheet Fuzzy Brand Name Match
A1: id | B1: title | C1: matchedBrand | D1: shopUrl | E1: tier | F1: score
A2: 1 | B2: Rioware x Bitespeed | E2: 0 | F2: 0.17142857
A3: 2 | B3: Zevar : AI Voice Review | E3: 0 | F3: 0.65
A4: 3 | B4: Tangerine Jewelry x Bitespeed : Connect | C4: Tangerine Bio Jewelry | D4: 62aa65.myshopify.com | E4: 2 | F4: 0.767
A5: 4 | B5: Nature Fab Store | E5: 0 | F5: 0.65
A6: 5 | B6: VIP x Bitespeed | E6: 0 | F6: 0.15
A7: 6 | B7: hardik@bitespeed.co - Mon, 09 Mar 2026 17:12:28 IST - Untitled | E7: 0 | F7: 0.225
A8: 7 | B8: Right4paws x Bitespeed | Trial Kickoff | E8: 0 | F8: 0.25
A9: 8 | B9: The Clothing Factory - Discussion | C9: The Clothing Factory | D9: the-clothing-factory-shop.myshopify.com | E9: 1 | F9: 1
A10: 9 | B10: tushita@bitespeed.co - Mon, 09 Mar 2026 17:44:13 IST - Untitled | E10: 0 | F10: 0.225
A11: 10 | B11: Dominic Smith and navneeth | Bitespeed | E11: 0 | F11: 0.65
A12: 11 | B12: V / Aaryaman | E12: 0 | F12: 0.1875
A13: 12 | B13: Onboarding Sync | E13: 0 | F13: 0.15
A14: 13 | B14: L1 Sync - Knowledge + Ticket Context | E14: 0 | F14: 0.21428571
A15: 14 | B15: Brustro : AI Voice Review | E15: 0 | F15: 0.2
A16: 15 | B16: Oregion x Bitespeed : Broadcast Ideas | E16: 0 | F16: 0.2
A17: 16 | B17: The Secret Of Tea - Market and WA | E17: 0 | F17: 0.53333333
A18: 17 | B18: rohan@bitespeed.co - Tue, 10 Mar 2026 12:03:54 IST - Untitled | E18: 0 | F18: 0.225
A19: 18 | B19: GleuHR x Bitespeed | Number Onboarding | C19: Gleuhr | D19: gleuhr.myshopify.com | E19: 1 | F19: 1
A20: 19 | B20: Bitespeed X Neeman's | E20: 0 | F20: 0.53333333
A21: 20 | B21: Frido X Bitespeed || AI Voice Broadcast | E21: 0 | F21: 0.21428571
A22: 21 | B22: Maskman - WA onboarding | E22: 0 | F22: 0.17142857
A23: 22 | B23: Cyclamen x Bitespeed | E23: 0 | F23: 0.15
A24: 23 | B24: L1 KT | ContextTransfer | Complete Handover | E24: 0 | F24: 0.1875
A25: 24 | B25: nandini@bitespeed.co - Tue, 10 Mar 2026 15:11:24 IST - Untitled | E25: 0 | F25: 0.65
A26: 25 | B26: Bitespeed - Books Closure for FY 2025–26 | E26: 0 | F26: 0.65
A27: 26 | B27: Dioste Connect | E27: 0 | F27: 0.21428571
A28: 27 | B28: Luka Originals x Bitespeed | E28: 0 | F28: 0.23333333
A29: 28 | B29: Truebrowns - Movement | E29: 0 | F29: 0.1875
A30: 29 | B30: Burger Bae x Bitespeed : AI Voice | E30: 0 | F30: 0.65
A31: 30 | B31: iThrive x Bitespeed AI Voice Review | E31: 0 | F31: 0.2
... A33: 32 | B33: Azhar Sheik and navneeth | Bitespeed | E33: 0 | F33: 0.2
A34: 33 | B34: Swashaa- Finance Discussions | C34: Swashaa | D34: swashaa.myshopify.com | E34: 1 | F34: 1
A35: 34 | B35: Burger Bae x Bitespeed : AI Voice | E35: 0 | F35: 0.65
A36: 35 | B36: Fridaycharm - Market | E36: 0 | F36: 0.2
A37: 36 | B37: AI-Driven Abandoned Cart Recovery Strategy | E37: 0 | F37: 0.65
A38: 37 | B38: Emcure x Bitspeed | Arth New number - Galact Catalgoue Integration | E38: 0 | F38: 0.65
A39: 38 | B39: The Secret of Tea - Marketing DB | E39: 0 | F39: 0.53333333
A40: 39 | B40: Theater x Bitespeed | Weekly Meet | E40: 0 | F40: 0.65
A41: 40 | B41: AI Voice : Review Call with Bitespeed | E41: 0 | F41: 0.2
...

Sheet Sheet4
A1: id | B1: title
A2: 1 | B2: Rioware x Bitespeed
A3: =A2+1 -> 2 | B3: Zevar : AI Voice Review
A4: =A3+1 -> 3 | B4: Tangerine Jewelry x Bitespeed : Connect
A5: =A4+1 -> 4 | B5: Nature Fab Store
A6: =A5+1 -> 5 | B6: VIP x Bitespeed
A7: =A6+1 -> 6 | B7: hardik@bitespeed.co - Mon, 09 Mar 2026 17:12:28 IST - Untitled
A8: =A7+1 -> 7 | B8: Right4paws x Bitespeed | Trial Kickoff
A9: =A8+1 -> 8 | B9: The Clothing Factory - Discussion
A10: =A9+1 -> 9 | B10: tushita@bitespeed.co - Mon, 09 Mar 2026 17:44:13 IST - Untitled
A11: =A10+1 -> 10 | B11: Dominic Smith and navneeth | Bitespeed
A12: =A11+1 -> 11 | B12: V / Aaryaman
A13: =A12+1 -> 12 | B13: Onboarding Sync
A14: =A13+1 -> 13 | B14: L1 Sync - Knowledge + Ticket Context
... A3332: =A3331+1 -> 3331 | B3332: |B| The Floristaa <> Bitespeed

Sheet Sheet1
A1: content | B1: shopUrl | C1: group_name
A2: Hi @918697472669, sharing the meeting link here: Nutriburst <> BiteSpeed | Broadcast Friday, 18 July · 2:30 – 3:15pm Time zone: Asia/Kolkata Google Meet joining info Video call link: https://meet.google.com/rgf-eepz-ocy Or dial: ‪(US) +1 409-444-2832‬ PIN: ‪130 733 830‬# More phone numbers: https://tel.meet/rgf-eepz-ocy?pin=6197395974761 cc: @918248768964 | B2: nutriburstindia.myshopify.com | C2: Nutriburst <> Bitespeed | E2: https://meet.google.com/rgf-eepz-ocy
A3: It was shared over email. Missed sharing here! Rooted actives <> BiteSpeed Tuesday, July 15 · 5:45 – 6:00pm Time zone: Asia/Kolkata Google Meet joining info Video call link: https://meet.google.com/jcq-ykvb-zcu Or dial: ‪(US) +1 501-737-0091‬ PIN: ‪328 406 375‬# More phone numbers: https://tel.meet/jcq-ykvb-zcu?pin=6356189667126 | B3: d3ccac.myshopify.com | C3: Rooted Actives <> BiteSpeed | E3: https://meet.google.com/jcq-ykvb-zcu
A4: It was shared over email. Missed sharing here! Rooted actives <> BiteSpeed Tuesday, July 15 · 5:45 – 6:00pm Time zone: Asia/Kolkata Google Meet joining info Video call link: https://meet.google.com/jcq-ykvb-zcu Or dial: ‪(US) +1 501-737-0091‬ PIN: ‪328 406 375‬# More phone numbers: https://tel.meet/jcq-ykvb-zcu?pin=6356189667126 | B4: d3ccac.myshopify.com | C4: Rooted Actives <> BiteSpeed | E4: https://meet.google.com/jcq-ykvb-zcu
A5: Hey @917204798940 as discussed, we will be rescheduling the call to tomorrow at 1 pm, once we have access to anudeep's email. Thank you!! Gramiyaa <> Bitespeed - WA Setup + Email warmup Thursday, 17 July · 1:00 – 1:45pm Video call link: https://meet.google.com/zgw-arja-vtu | B5: gramiyaa.myshopify.com | C5: Gramiyaa <> BiteSpeed | E5: https://meet.google.com/zgw-arja-vtu
A6: Tramontina <> BiteSpeed | Marketing DB Wednesday, July 16 · 1:00 – 1:30pm Time zone: Asia/Kolkata Google Meet joining info Video call link: https://meet.google.com/pih-nqdg-gtj Or dial: ‪(US) +1 319-435-9094‬ PIN: ‪917 361 229‬# More phone numbers: https://tel.meet/pih-nqdg-gtj?pin=1307645430481 | B6: tramontina-dubai.myshopify.com | C6: Tramontina <> BiteSpeed | E6: https://meet.google.com/pih-nqdg-gtj
A7: Tramontina <> BiteSpeed | Marketing DB Wednesday, July 16 · 1:00 – 1:30pm Time zone: Asia/Kolkata Google Meet joining info Video call link: https://meet.google.com/pih-nqdg-gtj Or dial: ‪(US) +1 319-435-9094‬ PIN: ‪917 361 229‬# More phone numbers: https://tel.meet/pih-nqdg-gtj?pin=1307645430481 | B7: tramontina-dubai.myshopify.com | C7: Tramontina <> BiteSpeed | E7: https://meet.google.com/pih-nqdg-gtj
A8: Hey @917204798940 as discussed, sharing the meeting link the meeting today: Gramiyaa <> Bitespeed - WA Setup + Email warmup Wednesday, 16 July · 3:30 – 4:30pm Video call link: https://meet.google.com/zgw-arja-vtu | B8: gramiyaa.myshopify.com | C8: Gramiyaa <> BiteSpeed | E8: https://meet.google.com/zgw-arja-vtu
A9: Shvetah <> BiteSpeed Monday, July 21 · 3:00 – 3:30pm Time zone: Asia/Kolkata Google Meet joining info Video call link: https://meet.google.com/qtd-ngde-awm Or dial: ‪(US) +1 219-401-0127‬ PIN: ‪903 098 292‬# More phone numbers: https://tel.meet/qtd-ngde-awm?pin=7240875804526 | B9: bf747e-3.myshopify.com | C9: Shvetah <> BiteSpeed | E9: https://meet.google.com/qtd-ngde-awm
A10: GuitarBro <> Bitespeed Wednesday, 16 July · 1:00 – 1:15pm Time zone: Asia/Kolkata Google Meet joining info Video call link: https://meet.google.com/vcm-tzqd-xff Or dial: ‪(US) +1 651-505-3968‬ PIN: ‪938 589 261‬# More phone numbers: https://tel.meet/vcm-tzqd-xff?pin=2856362213670 | B10: playguitarbro.myshopify.com | C10: Guitarbro <> BiteSpeed | E10: https://meet.google.com/vcm-tzqd-xff
A11: Sure, can we connect at 1:15 tomorrow please? Enem Products<>Bitespeed Wednesday, 16 July · 1:15 – 2:00pm Time zone: Asia/Kolkata Google Meet joining info Video call link: https://meet.google.com/sem-zozj-ykg Or dial: ‪(US) +1 347-966-3679‬ PIN: ‪608 364 014‬# More phone numbers: https://tel.meet/sem-zozj-ykg?pin=1388162406898 | B11: 3a2931-ce.myshopify.com | C11: Enem Products <> BiteSpeed | E11: https://meet.google.com/sem-zozj-ykg
A12: Sure, can we connect at 1:15 tomorrow please? Enem Products<>Bitespeed Wednesday, 16 July · 1:15 – 2:00pm Time zone: Asia/Kolkata Google Meet joining info Video call link: https://meet.google.com/sem-zozj-ykg Or dial: ‪(US) +1 347-966-3679‬ PIN: ‪608 364 014‬# More phone numbers: https://tel.meet/sem-zozj-ykg?pin=1388162406898 | B12: 3a2931-ce.myshopify.com | C12: Enem Products <> BiteSpeed | E12: https://meet.google.com/sem-zozj-ykg
A13: Arts of Devotion <> BiteSpeed Wednesday, July 16 · 10:30 – 11:00am Time zone: Asia/Kolkata Google Meet joining info Video call link: https://meet.google.com/oxp-udbi-qbk Or dial: ‪(US) +1 315-710-5023‬ PIN: ‪778 828 590‬# More phone numbers: https://tel.meet/oxp-udbi-qbk?pin=9117508488110 | B13: 8bbdfe-51.myshopify.com | C13: Arts of Devotion <> BiteSpeed | E13: https://meet.google.com/oxp-udbi-qbk
... A71: Guitar bro<>Bitespeed Thursday, 17 July · 2:30 – 3:00pm Time zone: Asia/Kolkata Google Meet joining info Video call link: https://meet.google.com/rsi-cmze-bde Or dial: ‪(US) +1 484-909-0092‬ PIN: ‪721 752 661‬# More phone numbers: https://tel.meet/rsi-cmze-bde?pin=8971518482010 @918602723031 | B71: playguitarbro.myshopify.com | C71: Guitarbro <> BiteSpeed | E71: https://meet.google.com/rsi-cmze-bde
A72: Hey @5213333912003 good morning!! Wanted to share a quick reminder for our call today. Looking forward to meeting you: Atletica <> Bitespeed - Broadcast + CSDB Thursday, 17 Jul · 11:00 – 12:00 PM UK time Video call link: https://meet.google.com/kxs-msgo-vnf | C72: Atletica <> BiteSpeed | E72: https://meet.google.com/kxs-msgo-vnf
A73: Hey @5213333912003 good morning!! Wanted to share a quick reminder for our call today. Looking forward to meeting you: Atletica <> Bitespeed - Broadcast + CSDB Thursday, 17 Jul · 11:00 – 12:00 PM UK time Video call link: https://meet.google.com/kxs-msgo-vnf | C73: Atletica <> BiteSpeed | E73: https://meet.google.com/kxs-msgo-vnf
A74: Hi @919967899900, sharing the meeting link here: Shakehands <> BiteSpeed Friday, 18 July · 4:00 – 4:45pm Time zone: Asia/Kolkata Google Meet joining info Video call link: https://meet.google.com/gir-jaav-akt Or dial: ‪(US) +1 321-586-0994‬ PIN: ‪678 431 388‬# More phone numbers: https://tel.meet/gir-jaav-akt?pin=2942895319272 | B74: shake-hands-f51f.myshopify.com | C74: Shakehands <> BiteSpeed | E74: https://meet.google.com/gir-jaav-akt
A75: Gemstone Galaxy <> Bitespeed - Catalog Friday, 18 July · 4:30 – 5:00pm Time zone: Asia/Kolkata Google Meet joining info Video call link: https://meet.google.com/sqt-amvk-xkp Or dial: ‪(US) +1 267-755-7916‬ PIN: ‪811 759 439‬# More phone numbers: https://tel.meet/sqt-amvk-xkp?pin=2718540047363 | B75: 60e3c1-3.myshopify.com | C75: Gemstone Galaxy <> BiteSpeed | E75: https://meet.google.com/sqt-amvk-xkp
A76: Paaduks <> BiteSpeed | Broadcast Friday, July 18 · 12:00 – 12:30pm Time zone: Asia/Kolkata Google Meet joining info Video call link: https://meet.google.com/emr-ywmx-izg Or dial: ‪(US) +1 929-266-1944‬ PIN: ‪291 123 046‬# More phone numbers: https://tel.meet/emr-ywmx-izg?pin=9336685364245 | B76: paaduks.myshopify.com | C76: Paaduks <> BiteSpeed | E76: https://meet.google.com/emr-ywmx-izg
A77: Paaduks <> BiteSpeed | Broadcast Friday, July 18 · 12:00 – 12:30pm Time zone: Asia/Kolkata Google Meet joining info Video call link: https://meet.google.com/emr-ywmx-izg Or dial: ‪(US) +1 929-266-1944‬ PIN: ‪291 123 046‬# More phone numbers: https://tel.meet/emr-ywmx-izg?pin=9336685364245 | B77: paaduks.myshopify.com | C77: Paaduks <> BiteSpeed | E77: https://meet.google.com/emr-ywmx-izg
A78: Moarmouz <> BiteSpeed | Support DB Friday, July 18 · 2:30 – 3:00pm Time zone: Asia/Kolkata Google Meet joining info Video call link: https://meet.google.com/ndc-nyjs-gfg Or dial: ‪(US) +1 515-605-0189‬ PIN: ‪831 564 805‬# More phone numbers: https://tel.meet/ndc-nyjs-gfg?pin=4366170774048 cc: @918548083112 | B78: molifestyle-3.myshopify.com | C78: Moarmouz <> BiteSpeed | E78: https://meet.google.com/ndc-nyjs-gfg
A79: Moarmouz <> BiteSpeed | Support DB Friday, July 18 · 2:30 – 3:00pm Time zone: Asia/Kolkata Google Meet joining info Video call link: https://meet.google.com/ndc-nyjs-gfg Or dial: ‪(US) +1 515-605-0189‬ PIN: ‪831 564 805‬# More phone numbers: https://tel.meet/ndc-nyjs-gfg?pin=4366170774048 cc: @918548083112 | B79: molifestyle-3.myshopify.com | C79: Moarmouz <> BiteSpeed | E79: https://meet.google.com/ndc-nyjs-gfg
A80: Rooted Actives <> BiteSpeed Friday, July 18 · 3:30 – 4:00pm Time zone: Asia/Kolkata Google Meet joining info Video call link: https://meet.google.com/nyb-ehfv-gdj Or dial: ‪(US) +1 904-900-0084‬ PIN: ‪458 846 361‬# More phone numbers: https://tel.meet/nyb-ehfv-gdj?pin=6898609802055 | B80: d3ccac.myshopify.com | C80: Rooted Actives <> BiteSpeed | E80: https://meet.google.com/nyb-ehfv-gdj
A81: Sure thing @919972555719 Here's the invite Senses India<>Bitespeed Monday, 21 Jul • 12:30 – 1:00 pm Google Meet joining info Video call link: https://meet.google.com/qra-fmxc-ogg Or dial: +1 563-503-5267 PIN: 420 112 710# More phone numbers: https://tel.meet/qra-fmxc-ogg?pin=9432491675929 | B81: senses-india.myshopify.com | C81: Senses India <> BiteSpeed | E81: https://meet.google.com/qra-fmxc-ogg
A82: Sure thing @919972555719 Here's the invite Senses India<>Bitespeed Monday, 21 Jul • 12:30 – 1:00 pm Google Meet joining info Video call link: https://meet.google.com/qra-fmxc-ogg Or dial: +1 563-503-5267 PIN: 420 112 710# More phone numbers: https://tel.meet/qra-fmxc-ogg?pin=9432491675929 | B82: senses-india.myshopify.com | C82: Senses India <> BiteSpeed | E82: https://meet.google.com/qra-fmxc-ogg
A83: Hi @917310699509, sharing the meeting link here: Terrana <> BiteSpeed | Onboarding Tuesday, 22 July · 1:00 – 1:45pm Time zone: Asia/Kolkata Google Meet joining info Video call link: https://meet.google.com/fpg-tbjp-sbs Or dial: ‪(US) +1 650-667-0390‬ PIN: ‪620 770 482‬# More phone numbers: https://tel.meet/fpg-tbjp-sbs?pin=7858277778015 | B83: df40ba-60.myshopify.com | C83: Terrana <> BiteSpeed | E83: https://meet.google.com/fpg-tbjp-sbs
A84: The Good Doll <> BiteSpeed | Support Dashboard Walkthrough Monday, 21 July · 4:00 – 4:30pm Video call link: https://meet.google.com/rfs-uyyn-ods | B84: theshopgoodgift.myshopify.com | C84: The Good Doll <> BiteSpeed | E84: https://meet.google.com/rfs-uyyn-ods
A85: Hey @447866223399 good morning!! I have joined the meeting link scheduled for us. Sharing the link below for your reference: Car Cologne <> Bitespeed - Broadcasts review Monday, 21 July · 4:00 – 5:00pm Video call link: https://meet.google.com/eau-czbc-xog | B85: carcalogne.myshopify.com | C85: Car Cologne <> BiteSpeed | E85: https://meet.google.com/eau-czbc-xog
... A218: Hi @918450955942, sharing the meeting link here: Svarn Jewels <> BiteSpeed | Broadcast Friday, 25 July · 5:00 – 5:45pm Time zone: Asia/Kolkata Google Meet joining info Video call link: https://meet.google.com/egh-xisf-ncu Or dial: ‪(US) +1 682-727-0375‬ PIN: ‪242 799 623‬# More phone numbers: https://tel.meet/egh-xisf-ncu?pin=6272036858570 | B218: b0db2e-04.myshopify.com | C218: Svarn Jewels <> Bitespeed | E218: https://meet.google.com/egh-xisf-ncu
A219: meet.google.com/zsa-igus-vna | B219: 3a2931-ce.myshopify.com | C219: Enem Products <> BiteSpeed | E219: #N/A
A220: https://meet.google.com/fzf-jext-bkd | B220: bummer-in.myshopify.com | C220: Bummer <> Bitespeed | E220: https://meet.google.com/fzf-jext-bkd
A221: Dring <> BiteSpeed Wednesday, 30 July · 5:30 – 6:15pm Video call link: https://meet.google.com/ene-bnxx-chf | B221: dring-india.myshopify.com | C221: Dring <> BiteSpeed | E221: https://meet.google.com/ene-bnxx-chf
A222: Wednesday, 30 July · 3:30 – 4:00pm Video call link: https://meet.google.com/waj-rsts-kpw | B222: minimal-mate.myshopify.com | C222: Everlasting <> BiteSpeed | E222: https://meet.google.com/waj-rsts-kpw
A223: Hey @916283528519, gentle reminder for our call Banno Swagger <> BiteSpeed Wednesday, 30 July · 3:00 – 3:30pm Video call link: https://meet.google.com/mei-fivi-cct | B223: bannosswagger.myshopify.com | C223: Banno Swagger <> BiteSpeed | E223: https://meet.google.com/mei-fivi-cct
A224: UNO Aroma <> BiteSpeed Saturday, 26 July · 10:30 – 11:00am Video call link: https://meet.google.com/tsb-zrrw-svr I'm on the call @917201888080 | B224: unoaroma-store.myshopify.com | C224: UNO Aroma <> BiteSpeed | E224: https://meet.google.com/tsb-zrrw-svr
A225: Hi @919970385173 as discussed on call, sharing the meeting link here: Krazy Caterpillar <> BiteSpeed Saturday 26 Jul · 10:30 – 11 AM Google Meet joining info Video call link: https://meet.google.com/qdw-fkqv-uzc Or dial: +1 385-645-7920 PIN: 474322636 More phone numbers: https://tel.meet/qdw-fkqv-uzc?pin=8413607093954 cc: @918309108052 | B225: krazy-caterpillar.myshopify.com | C225: Krazy Caterpillar <> BiteSpeed | E225: https://meet.google.com/qdw-fkqv-uzc
A226: Hi @918450955942 as discussed, sharing the meeting link here: Svarn Jewels <> BiteSpeed | Broadcast Saturday 26 Jul · 1 – 1:45 PM Google Meet joining info Video call link: https://meet.google.com/pku-xiuh-nqj Or dial: +1 929-266-1085 PIN: 361481623 More phone numbers: https://tel.meet/pku-xiuh-nqj?pin=5149125478767 | B226: b0db2e-04.myshopify.com | C226: Svarn Jewels <> Bitespeed | E226: https://meet.google.com/pku-xiuh-nqj
A227: Hi @919970385173 Thank you for connecting. As per our discussion, I have scheduled a 30-minute slot for the Tirla discussion tomorrow at 5 PM. Krazy Caterpillar <> BiteSpeed: Trial Discussion Monday, 28 July · 5:00 – 5:30pm Time zone: Asia/Kolkata Google Meet joining info Video call link: https://meet.google.com/rwv-gbyy-ykb cc @917827174101 @919650721486 Or dial: ‪(US) +1 240-903-4182‬ PIN: ‪294 667 511‬# More phone numbers: https://tel.meet/rwv-gbyy-ykb?pin=4728618939277 | B227: krazy-caterpillar.myshopify.com | C227: Krazy Caterpillar <> BiteSpeed | E227: https://meet.google.com/rwv-gbyy-ykb
A228: N4N <> BiteSpeed | Primary no. set up Monday, July 28 · 12:30 – 1:00pm Time zone: Asia/Kolkata Google Meet joining info Video call link: https://meet.google.com/qzo-xonf-sep Or dial: ‪(US) +1 470-228-6480‬ PIN: ‪194 195 746‬# More phone numbers: https://tel.meet/qzo-xonf-sep?pin=1002516926741 | B228: f18267-e3.myshopify.com | C228: Nature4Nature <> BiteSpeed | E228: https://meet.google.com/qzo-xonf-sep
A229: Soothi Syahi <> Bitespeed - Resume onboarding Monday, July 28 · 12:00 – 12:30pm Time zone: Asia/Kolkata Google Meet joining info Video call link: https://meet.google.com/djr-hpda-yqg Or dial: ‪(US) +1 442-900-4351‬ PIN: ‪767 490 454‬# More phone numbers: https://tel.meet/djr-hpda-yqg?pin=9229096644546 | B229: sootisyahi.myshopify.com | C229: Sooti Syahi <> BiteSpeed | E229: https://meet.google.com/djr-hpda-yqg
...
